Input.txt
1001 A L B 0.98 1000
1002 A L B 0.957 6000
1001 A L B 0.959 4000
1003 A L A 0.99 10000
1005 A L B 0.958 5000
1004 A L A 1.047 100000
1006 A L B 0.96 3000
1005 A L A 1.035 4500
1009 A L A 1.1 5000
1333 A L A 1.01 2000
1450 A L A 1.03 4000
1500 A L B 0.965 2000
1004 R 5
1111 A L B 0.995 5000
1112 A L B 0.994 5000
1005 A L A 0.979 500
1005 A L A 0.978 500
2001 A L B 1.0344 3500
2002 A L A 0.96 2888
3001 A L B 0.96 7888
1006 R 6
3002 A L B 0.99 60000
3003 A L B 0.98 7000
3004 A L A 1.02 1000
3005 A L A 1.032 7000
3006 A L A 1.032 1000
3003 A L B 0.958 1000
3007 A L A 1.08 5000
3008 A L A 1.1 5000
4001 A M B 200
4002 A M B 800
4003 A M B 4000
4004 A L A 1.2 9000
4004 A L A 1.33 8500
4005 A L A 1.23 6500
4006 A L A 1.34 6600
4007 A L A 1.25 7000
4008 A M B 50000
5001 A M A 10000
5002 A M A 50000
5003 A M A 7888
5004 A L B 0.97 1000
5005 A L B 0.95 40000
5006 A L B 0.94 10000
5007 A L B 0.93 2000
5009 A M A 50000
